<?xml version='1.0'?>
<sdf version='1.4'>
    <model name="ddbot">
        <static>false</static>
        <link name='base_link'>
            <pose>0 0 .1 0 0 0</pose>

            <collision name='collision'>
                <geometry>
                    <box>
                        <size>.4 .2 .1</size>
                    </box>
                </geometry>
            </collision>

            <visual name='visual'>
                <geometry>
                    <box>
                        <size>.4 .2 .1</size>
                    </box>
                </geometry>
            </visual>

            <collision name='caster_collision'>
                <pose>-0.15 0 -0.05 0 0 0</pose>
                <geometry>
                    <sphere>
                        <radius>.05</radius>
                    </sphere>
                </geometry>
                <surface>
                    <friction>
                        <ode>
                            <mu>0</mu>
                            <mu2>0</mu2>
                            <slip1>1.0</slip1>
                            <slip2>1.0</slip2>
                        </ode>
                    </friction>
                </surface>
            </collision>

            <visual name='caster_visual'>
                <pose>-0.15 0 -0.05 0 0 0</pose>
                <geometry>
                    <sphere>
                        <radius>.05</radius>
                    </sphere>
                </geometry>
            </visual>
        </link>


        <!-- <link name='caster'>
            <pose>-0.2 0 0 0 0 0</pose>
            <inertial>
                <mass>0.5</mass>
                <inertia>
                    <ixx>0.1</ixx>
                    <ixy>0</ixy>
                    <ixz>0</ixz>
                    <iyy>0.1</iyy>
                    <iyz>0</iyz>
                    <izz>0.1</izz>
                </inertia>
            </inertial>
            <visual name='visual'>
                <geometry>
                    <sphere>
                        <radius>.025</radius>
                    </sphere>
                </geometry>
            </visual>
            <collision name='collision'>
                <geometry>
                    <sphere>
                        <radius>.025</radius>
                    </sphere>
                </geometry>
            </collision>
        </link>

        <joint name='caster_wheel' type='ball'>
            <parent>base_link</parent>
            <child>caster</child>
        </joint> -->

        <link name="left_wheel">
            <pose>0.1 0.13 0.1 0 1.5707 1.5707</pose>

            <collision name="collision">
                <geometry>
                    <cylinder>
                        <radius>.1</radius>
                        <length>.05</length>
                    </cylinder>
                </geometry>
            </collision>
            <visual name="visual">
                <geometry>
                    <cylinder>
                        <radius>.1</radius>
                        <length>.05</length>
                    </cylinder>
                </geometry>
            </visual>
        </link>

        <link name="right_wheel">
            <pose>0.1 -0.13 0.1 0 1.5707 1.5707</pose>

            <collision name="collision">
                <geometry>
                    <cylinder>
                        <radius>.1</radius>
                        <length>.05</length>
                    </cylinder>
                </geometry>
            </collision>
            <visual name="visual">
                <geometry>
                    <cylinder>
                        <radius>.1</radius>
                        <length>.05</length>
                    </cylinder>
                </geometry>
            </visual>
        </link>

        <link name="camera_link">
            <pose>0 0 0.2 0 0 0</pose>
            <inertial>
                <mass>0.1</mass>
            </inertial>
            <collision name="collision">
                <geometry>
                    <box>
                        <size>0.073000 0.276000 0.072000</size>
                    </box>
                </geometry>
            </collision>
            <visual name="visual">
                <geometry>
                    <mesh>
                        <uri>model://kinect/meshes/kinect.dae</uri>
                    </mesh>
                </geometry>
            </visual>
            <sensor name="camera" type="depth">
                <update_rate>20</update_rate>
                <camera>
                    <horizontal_fov>1.047198</horizontal_fov>
                    <image>
                        <width>640</width>
                        <height>480</height>
                        <format>R8G8B8</format>
                    </image>
                    <clip>
                        <near>0.05</near>
                        <far>3</far>
                    </clip>
                </camera>

                <plugin name="plugin_name" filename="libgazebo_ros_camera.so">
                    <ros>
                        <namespace>/ddbot</namespace>
                        <argument>custom_camera/image_raw:=/ddbot/kinect_ros/image_raw</argument>
                        <argument>custom_camera/image_depth:=custom_camera/custom_image_depth</argument>
                        <argument>custom_camera/camera_info:=custom_camera/custom_info_raw</argument>
                        <argument>custom_camera/camera_info_depth:=custom_camera/custom_info_depth</argument>
                        <argument>custom_camera/points:=custom_camera/custom_points</argument>
                    </ros>
                    <camera_name>kinect_ros</camera_name>
                    <frame_name>camera_link</frame_name>
                    <hack_baseline>0.07</hack_baseline>
                    <min_depth>0.001</min_depth>
                </plugin>
            </sensor>

        </link>

        <!-- <include>
            <uri>model://kinect_ros</uri>
            <pose>0.2 0 0.2 0 0 0</pose>
        </include> -->

        <link name="imu_link">
            <!-- <visual>
                <geometry>
                    <box size="0.1 0.1 0.1"/>
                </geometry>
            </visual>

            <collision>
                <geometry>
                    <box size="0.1 0.1 0.1"/>
                </geometry>
            </collision> -->

            <!-- <xacro:box_inertia m="0.1" w="0.1" d="0.1" h="0.1"/> -->

            <sensor name="my_imu" type="imu">
                <always_on>true</always_on>
                <!-- Publish at 30 hz -->
                <update_rate>30</update_rate>
                <plugin name="my_imu_plugin" filename="libgazebo_ros_imu_sensor.so">
                    <ros>
                        <!-- Will publish to /imu/data -->
                        <namespace>/ddbot</namespace>
                        <argument>~/out:=imu</argument>
                    </ros>
                    <!-- frame_name ommited, will be "my_link" -->
                </plugin>
            </sensor>

        </link>

        <joint name="imu_joint" type="fixed">
            <pose>0 0 0 0 0 0</pose>
            <child>imu_link</child>
            <parent>base_link</parent>
        </joint>

        <joint name="kinect_joint" type="fixed">
            <pose>0 0 0 0 0 0</pose>
            <child>camera_link</child>
            <parent>base_link</parent>
        </joint>

        <joint name="left_wheel_hinge" type="revolute">
            <pose>0 0 -0.03 0 0 0</pose>
            <child>left_wheel</child>
            <parent>base_link</parent>
            <axis>
                <xyz>0 1 0</xyz>
            </axis>
        </joint>

        <joint name="right_wheel_hinge" type="revolute">
            <pose>0 0 0.03 0 0 0</pose>
            <child>right_wheel</child>
            <parent>base_link</parent>
            <axis>
                <xyz>0 1 0</xyz>
            </axis>
        </joint>

        <!-- <plugin name="ddbot" filename="libdd_control.so"/> -->
        <!-- <plugin name="p3d" filename="libgazebo_ros_p3d.so">
            <ros>
                <namespace>/ddbot</namespace>
            </ros>
            <update_rate>50</<update_rate>
            <body_name>base_link</body_name>
            <frame_name>base_link</frame_name>
        </plugin> -->

        <plugin name="joint_states" filename="libgazebo_ros_joint_state_publisher.so">
            <joint_name>right_wheel_hinge</joint_name>
            <joint_name>left_wheel_hinge</joint_name>
        </plugin>

        <plugin name='diff_drive' filename='libgazebo_ros_diff_drive.so'>

            <ros>
                <namespace>/ddbot</namespace>
                <argument>cmd_vel:=cmd_vel</argument>
                <argument>odom:=odom</argument>
            </ros>

            <left_joint>left_wheel_hinge</left_joint>
            <right_joint>right_wheel_hinge</right_joint>

            <wheel_separation>0.26</wheel_separation>
            <wheel_diameter>0.2</wheel_diameter>

            <max_wheel_torque>20</max_wheel_torque>
            <max_wheel_acceleration>1.0</max_wheel_acceleration>

            <publish_odom>true</publish_odom>
            <publish_odom_tf>true</publish_odom_tf>
            <publish_wheel_tf>true</publish_wheel_tf>

            <odometry_frame>odom</odometry_frame>
            <robot_base_frame>base_link</robot_base_frame>

        </plugin>
    </model>
</sdf>